Workbook

Sheet минимумы и максимумы
B1: school | C1: kindergarten | D1: polyclinic | E1: supermarket | F1: PVZ | G1: obshepit | H1: hotel | I1: BC | J1: bank | K1: stop | L1: to_centre | M1: condition | N1: value | O1: b_n | P1: zone | Q1: floors | R1: s_base | S1: complexity
A2: min | B2: 0 | C2: 0 | D2: 0 | E2: 0 | F2: 0 | G2: 0 | H2: 0 | I2: 0 | J2: 0 | K2: 0 | L2: 0 | M2: 1 | N2: 0 | O2: 0 | P2: 0 | Q2: 0 | R2: 0 | S2: 1
A3: max (k=1,5) | B3: 5 | C3: 10 | D3: 3 | E3: 24 | F3: 25 | G3: 53 | H3: 15 | I3: 18 | J3: 5 | K3: 31 | L3: 22197 | M3: 4 | N3: 1 | O3: 1 | P3: 4 | Q3: 6 | R3: 2273 | S3: 4
A4: max (k=3) | B4: 8 | C4: 16 | D4: 4 | E4: 37 | F4: 38 | G4: 83 | H4: 24 | I4: 28 | J4: 8 | K4: 47 | L4: 33352 | M4: 4 | N4: 1 | O4: 1 | P4: 4 | Q4: 9 | R4: 3476 | S4: 4
A7: итоговые лучшие
B8: school | C8: kindergarten | D8: polyclinic | E8: supermarket | F8: PVZ | G8: obshepit | H8: hotel | I8: BC | J8: bank | K8: stop | L8: to_centre | M8: condition | N8: value | O8: b_n | P8: zone | Q8: floors | R8: s_base | S8: complexity
A9: min | B9: 0 | C9: 0 | D9: 0 | E9: 0 | F9: 0 | G9: 0 | H9: 0 | I9: 0 | J9: 0 | K9: 0 | L9: 0 | M9: 1 | N9: 0 | O9: 0 | P9: 0 | Q9: 0 | R9: 0 | S9: 1
A10: max | B10: 9 | C10: 10 | D10: 3 | E10: 24 | F10: 29 | G10: 53 | H10: 15 | I10: 18 | J10: 14 | K10: 28 | L10: 22197 | M10: 4 | N10: 1 | O10: 1 | P10: 4 | Q10: 6 | R10: 3476 | S10: 4
F14: min (минимум) | G14: max (максимум) | I14: min (минимум) | J14: max (максимум)
D15: Кол-во городских сервисов в 5-минутной пешеходной зоне от заброшенного здания | E15: school (школа) | F15: 0 | G15: 9 | H15: to_centre (расстояние до центра города) | I15: 0 | J15: 22197
E16: kindergarten (детский сад) | F16: 0 | G16: 10 | H16: condition (состояние здания) | I16: 1 | J16: 4
E17: polyclinic (поликлиника) | F17: 0 | G17: 3 | H17: value (наличие статуса ОКН) | I17: 0 | J17: 1
E18: supermarket (продуктовый магазин) | F18: 0 | G18: 24 | H18: b_n (бывшее назначение) | I18: 0 | J18: 1
E19: PVZ (пункт выдачи заказов) | F19: 0 | G19: 29 | H19: zone (функциональная зона) | I19: 0 | J19: 4
E20: obshepit (заведение общественного питания) | F20: 0 | G20: 53 | H20: floors (кол-во этажей) | I20: 0 | J20: 6
E21: hotel (отель/гостиница) | F21: 0 | G21: 15 | H21: s_base (площадь основания здания) | I21: 0 | J21: 3476
E22: BC (бизнес-центр) | F22: 0 | G22: 18 | H22: complexity (сложность формы здания) | I22: 1 | J22: 4
E23: bank (отделение банка) | F23: 0 | G23: 14
E24: stop (остановка общественного транспорта) | F24: 0 | G24: 28

Sheet исходные данные
A1: id | B1: vosstanovleno | C1: sneseno | D1: school | E1: kindergarten | F1: polyclinic | G1: supermarket | H1: PVZ | I1: obshepit | J1: hotel | K1: BC | L1: bank | M1: stop | N1: to_centre | O1: condition | P1: value | Q1: b_n | R1: zone | S1: floors | T1: s_base | U1: complexity
A2: 1 | B2: 0 | C2: 0 | D2: 4 | E2: 8 | F2: 1 | G2: 16 | H2: 20 | I2: 63 | J2: 22 | K2: 6 | L2: 11 | M2: 15 | N2: 2950.1895 | O2: 2 | P2: 1 | Q2: 1 | R2: 3 | S2: 3 | T2: 1134 | U2: 4
A3: 2 | B3: 0 | C3: 0 | D3: 0 | E3: 0 | F3: 0 | G3: 0 | H3: 0 | I3: 1 | J3: 0 | K3: 1 | L3: 0 | M3: 1 | N3: 4015.3889 | O3: 1 | P3: 1 | Q3: 0 | R3: 1 | S3: 2 | T3: 3997 | U3: 2
A4: 3 | B4: 0 | C4: 0 | D4: 4 | E4: 4 | F4: 0 | G4: 9 | H4: 9 | I4: 53 | J4: 12 | K4: 5 | L4: 2 | M4: 12 | N4: 1994.4867 | O4: 1 | P4: 0 | Q4: 1 | R4: 3 | S4: 2 | T4: 189 | U4: 2
A5: 5 | B5: 0 | C5: 0 | D5: 2 | E5: 7 | F5: 0 | G5: 6 | H5: 5 | I5: 55 | J5: 7 | K5: 1 | L5: 3 | M5: 9 | N5: 2100.1041 | O5: 3 | P5: 1 | Q5: 1 | R5: 3 | S5: 3 | T5: 645 | U5: 3
A6: 6 | B6: 0 | C6: 0 | D6: 4 | E6: 6 | F6: 0 | G6: 5 | H6: 5 | I6: 54 | J6: 9 | K6: 1 | L6: 3 | M6: 9 | N6: 2160.4127 | O6: 4 | P6: 1 | Q6: 1 | R6: 4 | S6: 2 | T6: 1292 | U6: 4
A7: 7 | B7: 0 | C7: 0 | D7: 4 | E7: 6 | F7: 0 | G7: 7 | H7: 9 | I7: 64 | J7: 13 | K7: 4 | L7: 3 | M7: 8 | N7: 2350.988 | O7: 2 | P7: 0 | Q7: 1 | R7: 4 | S7: 2 | T7: 914 | U7: 4
A8: 17 | B8: 0 | C8: 0 | D8: 0 | E8: 0 | F8: 0 | G8: 3 | H8: 2 | I8: 36 | J8: 1 | K8: 0 | L8: 0 | M8: 7 | N8: 5361.1487 | O8: 3 | P8: 0 | Q8: 1 | R8: 3 | S8: 2 | T8: 139 | U8: 1
A9: 20 | B9: 0 | C9: 0 | D9: 1 | E9: 1 | F9: 1 | G9: 9 | H9: 8 | I9: 19 | J9: 9 | K9: 13 | L9: 3 | M9: 16 | N9: 4156.612 | O9: 2 | P9: 1 | Q9: 1 | R9: 3 | S9: 3 | T9: 1311 | U9: 3
A10: 21 | B10: 0 | C10: 1 | D10: 1 | E10: 3 | F10: 0 | G10: 9 | H10: 11 | I10: 32 | J10: 7 | K10: 0 | L10: 0 | M10: 10 | N10: 5138.2025 | O10: 1 | P10: 0 | Q10: 1 | R10: 4 | S10: 3 | T10: 400 | U10: 4
A11: 22 | B11: 0 | C11: 0 | D11: 4 | E11: 6 | F11: 0 | G11: 5 | H11: 5 | I11: 16 | J11: 3 | K11: 8 | L11: 0 | M11: 17 | N11: 3970.0577 | O11: 4 | P11: 0 | Q11: 1 | R11: 3 | S11: 4 | T11: 931 | U11: 1
A12: 27 | B12: 1 | C12: 0 | D12: 4 | E12: 6 | F12: 1 | G12: 20 | H12: 20 | I12: 45 | J12: 13 | K12: 5 | L12: 10 | M12: 17 | N12: 3300.0404 | O12: 3 | P12: 1 | Q12: 1 | R12: 4 | S12: 2 | T12: 274 | U12: 2
A13: 29 | B13: 0 | C13: 0 | D13: 7 | E13: 5 | F13: 2 | G13: 14 | H13: 16 | I13: 50 | J13: 16 | K13: 13 | L13: 7 | M13: 20 | N13: 2690.8462 | O13: 3 | P13: 1 | Q13: 1 | R13: 4 | S13: 2 | T13: 383 | U13: 3
... A432: 553 | B432: 0 | C432: 0 | D432: 0 | E432: 0 | F432: 0 | G432: 0 | H432: 0 | I432: 2 | J432: 0 | K432: 0 | L432: 0 | M432: 3 | N432: 9308.7609 | O432: 2 | P432: 0 | Q432: 0 | R432: 3 | S432: 1 | T432: 1168 | U432: 3

Sheet нормал итог
A1: id | B1: vosstanovleno | C1: sneseno | D1: school | E1: kindergarten | F1: polyclinic | G1: supermarket | H1: PVZ | I1: obshepit | J1: hotel | K1: BC | L1: bank | M1: stop | N1: to_centre | O1: condition | P1: value | Q1: b_n | R1: zone | S1: floors | T1: s_base | U1: complexity
A2: 1 | B2: 0 | C2: 0 | D2: =IF('исходные данные'!D2>'минимумы и максимумы'!B$10,100,('исходные данные'!D2-'минимумы и максимумы'!B$9)/('минимумы и максимумы'!B$10-'минимумы и максимумы'!B$9)*100) -> 44.444444 | E2: =IF('исходные данные'!E2>'минимумы и максимумы'!C$10,100,('исходные данные'!E2-'минимумы и максимумы'!C$9)/('минимумы и максимумы'!C$10-'минимумы и максимумы'!C$9)*100) -> 80 | F2: =IF('исходные данные'!F2>'минимумы и максимумы'!D$10,100,('исходные данные'!F2-'минимумы и максимумы'!D$9)/('минимумы и максимумы'!D$10-'минимумы и максимумы'!D$9)*100) -> 33.333333 | G2: =IF('исходные данные'!G2>'минимумы и максимумы'!E$10,100,('исходные данные'!G2-'минимумы и максимумы'!E$9)/('минимумы и максимумы'!E$10-'минимумы и максимумы'!E$9)*100) -> 66.666667 | H2: =IF('исходные данные'!H2>'минимумы и максимумы'!F$10,100,('исходные данные'!H2-'минимумы и максимумы'!F$9)/('минимумы и максимумы'!F$10-'минимумы и максимумы'!F$9)*100) -> 68.965517 | I2: =IF('исходные данные'!I2>'минимумы и максимумы'!G$10,100,('исходные данные'!I2-'минимумы и максимумы'!G$9)/('минимумы и максимумы'!G$10-'минимумы и максимумы'!G$9)*100) -> 100 | J2: =IF('исходные данные'!J2>'минимумы и максимумы'!H$10,100,('исходные данные'!J2-'минимумы и максимумы'!H$9)/('минимумы и максимумы'!H$10-'минимумы и максимумы'!H$9)*100) -> 100 | K2: =IF('исходные данные'!K2>'минимумы и максимумы'!I$10,100,('исходные данные'!K2-'минимумы и максимумы'!I$9)/('минимумы и максимумы'!I$10-'минимумы и максимумы'!I$9)*100) -> 33.333333 | ... U2: =IF('исходные данные'!U2>'минимумы и максимумы'!S$10,100,('исходные данные'!U2-'минимумы и максимумы'!S$9)/('минимумы и максимумы'!S$10-'минимумы и максимумы'!S$9)*100) -> 100
A3: 2 | B3: 0 | C3: 0 | D3: =IF('исходные данные'!D3>'минимумы и максимумы'!B$10,100,('исходные данные'!D3-'минимумы и максимумы'!B$9)/('минимумы и максимумы'!B$10-'минимумы и максимумы'!B$9)*100) -> 0 | E3: =IF('исходные данные'!E3>'минимумы и максимумы'!C$10,100,('исходные данные'!E3-'минимумы и максимумы'!C$9)/('минимумы и максимумы'!C$10-'минимумы и максимумы'!C$9)*100) -> 0 | F3: =IF('исходные данные'!F3>'минимумы и максимумы'!D$10,100,('исходные данные'!F3-'минимумы и максимумы'!D$9)/('минимумы и максимумы'!D$10-'минимумы и максимумы'!D$9)*100) -> 0 | G3: =IF('исходные данные'!G3>'минимумы и максимумы'!E$10,100,('исходные данные'!G3-'минимумы и максимумы'!E$9)/('минимумы и максимумы'!E$10-'минимумы и максимумы'!E$9)*100) -> 0 | H3: =IF('исходные данные'!H3>'минимумы и максимумы'!F$10,100,('исходные данные'!H3-'минимумы и максимумы'!F$9)/('минимумы и максимумы'!F$10-'минимумы и максимумы'!F$9)*100) -> 0 | I3: =IF('исходные данные'!I3>'минимумы и максимумы'!G$10,100,('исходные данные'!I3-'минимумы и максимумы'!G$9)/('минимумы и максимумы'!G$10-'минимумы и максимумы'!G$9)*100) -> 1.8867925 | J3: =IF('исходные данные'!J3>'минимумы и максимумы'!H$10,100,('исходные данные'!J3-'минимумы и максимумы'!H$9)/('минимумы и максимумы'!H$10-'минимумы и максимумы'!H$9)*100) -> 0 | K3: =IF('исходные данные'!K3>'минимумы и максимумы'!I$10,100,('исходные данные'!K3-'минимумы и максимумы'!I$9)/('минимумы и максимумы'!I$10-'минимумы и максимумы'!I$9)*100) -> 5.5555556 | ... U3: =IF('исходные данные'!U3>'минимумы и максимумы'!S$10,100,('исходные данные'!U3-'минимумы и максимумы'!S$9)/('минимумы и максимумы'!S$10-'минимумы и максимумы'!S$9)*100) -> 33.333333
A4: 3 | B4: 0 | C4: 0 | D4: =IF('исходные данные'!D4>'минимумы и максимумы'!B$10,100,('исходные данные'!D4-'минимумы и максимумы'!B$9)/('минимумы и максимумы'!B$10-'минимумы и максимумы'!B$9)*100) -> 44.444444 | E4: =IF('исходные данные'!E4>'минимумы и максимумы'!C$10,100,('исходные данные'!E4-'минимумы и максимумы'!C$9)/('минимумы и максимумы'!C$10-'минимумы и максимумы'!C$9)*100) -> 40 | F4: =IF('исходные данные'!F4>'минимумы и максимумы'!D$10,100,('исходные данные'!F4-'минимумы и максимумы'!D$9)/('минимумы и максимумы'!D$10-'минимумы и максимумы'!D$9)*100) -> 0 | G4: =IF('исходные данные'!G4>'минимумы и максимумы'!E$10,100,('исходные данные'!G4-'минимумы и максимумы'!E$9)/('минимумы и максимумы'!E$10-'минимумы и максимумы'!E$9)*100) -> 37.5 | H4: =IF('исходные данные'!H4>'минимумы и максимумы'!F$10,100,('исходные данные'!H4-'минимумы и максимумы'!F$9)/('минимумы и максимумы'!F$10-'минимумы и максимумы'!F$9)*100) -> 31.034483 | I4: =IF('исходные данные'!I4>'минимумы и максимумы'!G$10,100,('исходные данные'!I4-'минимумы и максимумы'!G$9)/('минимумы и максимумы'!G$10-'минимумы и максимумы'!G$9)*100) -> 100 | J4: =IF('исходные данные'!J4>'минимумы и максимумы'!H$10,100,('исходные данные'!J4-'минимумы и максимумы'!H$9)/('минимумы и максимумы'!H$10-'минимумы и максимумы'!H$9)*100) -> 80 | K4: =IF('исходные данные'!K4>'минимумы и максимумы'!I$10,100,('исходные данные'!K4-'минимумы и максимумы'!I$9)/('минимумы и максимумы'!I$10-'минимумы и максимумы'!I$9)*100) -> 27.777778 | ... U4: =IF('исходные данные'!U4>'минимумы и максимумы'!S$10,100,('исходные данные'!U4-'минимумы и максимумы'!S$9)/('минимумы и максимумы'!S$10-'минимумы и максимумы'!S$9)*100) -> 33.333333
A5: 5 | B5: 0 | C5: 0 | D5: =IF('исходные данные'!D5>'минимумы и максимумы'!B$10,100,('исходные данные'!D5-'минимумы и максимумы'!B$9)/('минимумы и максимумы'!B$10-'минимумы и максимумы'!B$9)*100) -> 22.222222 | E5: =IF('исходные данные'!E5>'минимумы и максимумы'!C$10,100,('исходные данные'!E5-'минимумы и максимумы'!C$9)/('минимумы и максимумы'!C$10-'минимумы и максимумы'!C$9)*100) -> 70 | F5: =IF('исходные данные'!F5>'минимумы и максимумы'!D$10,100,('исходные данные'!F5-'минимумы и максимумы'!D$9)/('минимумы и максимумы'!D$10-'минимумы и максимумы'!D$9)*100) -> 0 | G5: =IF('исходные данные'!G5>'минимумы и максимумы'!E$10,100,('исходные данные'!G5-'минимумы и максимумы'!E$9)/('минимумы и максимумы'!E$10-'минимумы и максимумы'!E$9)*100) -> 25 | H5: =IF('исходные данные'!H5>'минимумы и максимумы'!F$10,100,('исходные данные'!H5-'минимумы и максимумы'!F$9)/('минимумы и максимумы'!F$10-'минимумы и максимумы'!F$9)*100) -> 17.241379 | I5: =IF('исходные данные'!I5>'минимумы и максимумы'!G$10,100,('исходные данные'!I5-'минимумы и максимумы'!G$9)/('минимумы и максимумы'!G$10-'минимумы и максимумы'!G$9)*100) -> 100 | J5: =IF('исходные данные'!J5>'минимумы и максимумы'!H$10,100,('исходные данные'!J5-'минимумы и максимумы'!H$9)/('минимумы и максимумы'!H$10-'минимумы и максимумы'!H$9)*100) -> 46.666667 | K5: =IF('исходные данные'!K5>'минимумы и максимумы'!I$10,100,('исходные данные'!K5-'минимумы и максимумы'!I$9)/('минимумы и максимумы'!I$10-'минимумы и максимумы'!I$9)*100) -> 5.5555556 | ... U5: =IF('исходные данные'!U5>'минимумы и максимумы'!S$10,100,('исходные данные'!U5-'минимумы и максимумы'!S$9)/('минимумы и максимумы'!S$10-'минимумы и максимумы'!S$9)*100) -> 66.666667
A6: 6 | B6: 0 | C6: 0 | D6: =IF('исходные данные'!D6>'минимумы и максимумы'!B$10,100,('исходные данные'!D6-'минимумы и максимумы'!B$9)/('минимумы и максимумы'!B$10-'минимумы и максимумы'!B$9)*100) -> 44.444444 | E6: =IF('исходные данные'!E6>'минимумы и максимумы'!C$10,100,('исходные данные'!E6-'минимумы и максимумы'!C$9)/('минимумы и максимумы'!C$10-'минимумы и максимумы'!C$9)*100) -> 60 | F6: =IF('исходные данные'!F6>'минимумы и максимумы'!D$10,100,('исходные данные'!F6-'минимумы и максимумы'!D$9)/('минимумы и максимумы'!D$10-'минимумы и максимумы'!D$9)*100) -> 0 | G6: =IF('исходные данные'!G6>'минимумы и максимумы'!E$10,100,('исходные данные'!G6-'минимумы и максимумы'!E$9)/('минимумы и максимумы'!E$10-'минимумы и максимумы'!E$9)*100) -> 20.833333 | H6: =IF('исходные данные'!H6>'минимумы и максимумы'!F$10,100,('исходные данные'!H6-'минимумы и максимумы'!F$9)/('минимумы и максимумы'!F$10-'минимумы и максимумы'!F$9)*100) -> 17.241379 | I6: =IF('исходные данные'!I6>'минимумы и максимумы'!G$10,100,('исходные данные'!I6-'минимумы и максимумы'!G$9)/('минимумы и максимумы'!G$10-'минимумы и максимумы'!G$9)*100) -> 100 | J6: =IF('исходные данные'!J6>'минимумы и максимумы'!H$10,100,('исходные данные'!J6-'минимумы и максимумы'!H$9)/('минимумы и максимумы'!H$10-'минимумы и максимумы'!H$9)*100) -> 60 | K6: =IF('исходные данные'!K6>'минимумы и максимумы'!I$10,100,('исходные данные'!K6-'минимумы и максимумы'!I$9)/('минимумы и максимумы'!I$10-'минимумы и максимумы'!I$9)*100) -> 5.5555556 | ... U6: =IF('исходные данные'!U6>'минимумы и максимумы'!S$10,100,('исходные данные'!U6-'минимумы и максимумы'!S$9)/('минимумы и максимумы'!S$10-'минимумы и максимумы'!S$9)*100) -> 100
A7: 7 | B7: 0 | C7: 0 | D7: =IF('исходные данные'!D7>'минимумы и максимумы'!B$10,100,('исходные данные'!D7-'минимумы и максимумы'!B$9)/('минимумы и максимумы'!B$10-'минимумы и максимумы'!B$9)*100) -> 44.444444 | E7: =IF('исходные данные'!E7>'минимумы и максимумы'!C$10,100,('исходные данные'!E7-'минимумы и максимумы'!C$9)/('минимумы и максимумы'!C$10-'минимумы и максимумы'!C$9)*100) -> 60 | F7: =IF('исходные данные'!F7>'минимумы и максимумы'!D$10,100,('исходные данные'!F7-'минимумы и максимумы'!D$9)/('минимумы и максимумы'!D$10-'минимумы и максимумы'!D$9)*100) -> 0 | G7: =IF('исходные данные'!G7>'минимумы и максимумы'!E$10,100,('исходные данные'!G7-'минимумы и максимумы'!E$9)/('минимумы и максимумы'!E$10-'минимумы и максимумы'!E$9)*100) -> 29.166667 | H7: =IF('исходные данные'!H7>'минимумы и максимумы'!F$10,100,('исходные данные'!H7-'минимумы и максимумы'!F$9)/('минимумы и максимумы'!F$10-'минимумы и максимумы'!F$9)*100) -> 31.034483 | I7: =IF('исходные данные'!I7>'минимумы и максимумы'!G$10,100,('исходные данные'!I7-'минимумы и максимумы'!G$9)/('минимумы и максимумы'!G$10-'минимумы и максимумы'!G$9)*100) -> 100 | J7: =IF('исходные данные'!J7>'минимумы и максимумы'!H$10,100,('исходные данные'!J7-'минимумы и максимумы'!H$9)/('минимумы и максимумы'!H$10-'минимумы и максимумы'!H$9)*100) -> 86.666667 | K7: =IF('исходные данные'!K7>'минимумы и максимумы'!I$10,100,('исходные данные'!K7-'минимумы и максимумы'!I$9)/('минимумы и максимумы'!I$10-'минимумы и максимумы'!I$9)*100) -> 22.222222 | ... U7: =IF('исходные данные'!U7>'минимумы и максимумы'!S$10,100,('исходные данные'!U7-'минимумы и максимумы'!S$9)/('минимумы и максимумы'!S$10-'минимумы и максимумы'!S$9)*100) -> 100
A8: 17 | B8: 0 | C8: 0 | D8: =IF('исходные данные'!D8>'минимумы и максимумы'!B$10,100,('исходные данные'!D8-'минимумы и максимумы'!B$9)/('минимумы и максимумы'!B$10-'минимумы и максимумы'!B$9)*100) -> 0 | E8: =IF('исходные данные'!E8>'минимумы и максимумы'!C$10,100,('исходные данные'!E8-'минимумы и максимумы'!C$9)/('минимумы и максимумы'!C$10-'минимумы и максимумы'!C$9)*100) -> 0 | F8: =IF('исходные данные'!F8>'минимумы и максимумы'!D$10,100,('исходные данные'!F8-'минимумы и максимумы'!D$9)/('минимумы и максимумы'!D$10-'минимумы и максимумы'!D$9)*100) -> 0 | G8: =IF('исходные данные'!G8>'минимумы и максимумы'!E$10,100,('исходные данные'!G8-'минимумы и максимумы'!E$9)/('минимумы и максимумы'!E$10-'минимумы и максимумы'!E$9)*100) -> 12.5 | H8: =IF('исходные данные'!H8>'минимумы и максимумы'!F$10,100,('исходные данные'!H8-'минимумы и максимумы'!F$9)/('минимумы и максимумы'!F$10-'минимумы и максимумы'!F$9)*100) -> 6.8965517 | I8: =IF('исходные данные'!I8>'минимумы и максимумы'!G$10,100,('исходные данные'!I8-'минимумы и максимумы'!G$9)/('минимумы и максимумы'!G$10-'минимумы и максимумы'!G$9)*100) -> 67.924528 | J8: =IF('исходные данные'!J8>'минимумы и максимумы'!H$10,100,('исходные данные'!J8-'минимумы и максимумы'!H$9)/('минимумы и максимумы'!H$10-'минимумы и максимумы'!H$9)*100) -> 6.6666667 | K8: =IF('исходные данные'!K8>'минимумы и максимумы'!I$10,100,('исходные данные'!K8-'минимумы и максимумы'!I$9)/('минимумы и максимумы'!I$10-'минимумы и максимумы'!I$9)*100) -> 0 | ... U8: =IF('исходные данные'!U8>'минимумы и максимумы'!S$10,100,('исходные данные'!U8-'минимумы и максимумы'!S$9)/('минимумы и максимумы'!S$10-'минимумы и максимумы'!S$9)*100) -> 0
A9: 20 | B9: 0 | C9: 0 | D9: =IF('исходные данные'!D9>'минимумы и максимумы'!B$10,100,('исходные данные'!D9-'минимумы и максимумы'!B$9)/('минимумы и максимумы'!B$10-'минимумы и максимумы'!B$9)*100) -> 11.111111 | E9: =IF('исходные данные'!E9>'минимумы и максимумы'!C$10,100,('исходные данные'!E9-'минимумы и максимумы'!C$9)/('минимумы и максимумы'!C$10-'минимумы и максимумы'!C$9)*100) -> 10 | F9: =IF('исходные данные'!F9>'минимумы и максимумы'!D$10,100,('исходные данные'!F9-'минимумы и максимумы'!D$9)/('минимумы и максимумы'!D$10-'минимумы и максимумы'!D$9)*100) -> 33.333333 | G9: =IF('исходные данные'!G9>'минимумы и максимумы'!E$10,100,('исходные данные'!G9-'минимумы и максимумы'!E$9)/('минимумы и максимумы'!E$10-'минимумы и максимумы'!E$9)*100) -> 37.5 | H9: =IF('исходные данные'!H9>'минимумы и максимумы'!F$10,100,('исходные данные'!H9-'минимумы и максимумы'!F$9)/('минимумы и максимумы'!F$10-'минимумы и максимумы'!F$9)*100) -> 27.586207 | I9: =IF('исходные данные'!I9>'минимумы и максимумы'!G$10,100,('исходные данные'!I9-'минимумы и максимумы'!G$9)/('минимумы и максимумы'!G$10-'минимумы и максимумы'!G$9)*100) -> 35.849057 | J9: =IF('исходные данные'!J9>'минимумы и максимумы'!H$10,100,('исходные данные'!J9-'минимумы и максимумы'!H$9)/('минимумы и максимумы'!H$10-'минимумы и максимумы'!H$9)*100) -> 60 | K9: =IF('исходные данные'!K9>'минимумы и максимумы'!I$10,100,('исходные данные'!K9-'минимумы и максимумы'!I$9)/('минимумы и максимумы'!I$10-'минимумы и максимумы'!I$9)*100) -> 72.222222 | ... U9: =IF('исходные данные'!U9>'минимумы и максимумы'!S$10,100,('исходные данные'!U9-'минимумы и максимумы'!S$9)/('минимумы и максимумы'!S$10-'минимумы и максимумы'!S$9)*100) -> 66.666667
A10: 21 | B10: 0 | C10: 1 | D10: =IF('исходные данные'!D10>'минимумы и максимумы'!B$10,100,('исходные данные'!D10-'минимумы и максимумы'!B$9)/('минимумы и максимумы'!B$10-'минимумы и максимумы'!B$9)*100) -> 11.111111 | E10: =IF('исходные данные'!E10>'минимумы и максимумы'!C$10,100,('исходные данные'!E10-'минимумы и максимумы'!C$9)/('минимумы и максимумы'!C$10-'минимумы и максимумы'!C$9)*100) -> 30 | F10: =IF('исходные данные'!F10>'минимумы и максимумы'!D$10,100,('исходные данные'!F10-'минимумы и максимумы'!D$9)/('минимумы и максимумы'!D$10-'минимумы и максимумы'!D$9)*100) -> 0 | G10: =IF('исходные данные'!G10>'минимумы и максимумы'!E$10,100,('исходные данные'!G10-'минимумы и максимумы'!E$9)/('минимумы и максимумы'!E$10-'минимумы и максимумы'!E$9)*100) -> 37.5 | H10: =IF('исходные данные'!H10>'минимумы и максимумы'!F$10,100,('исходные данные'!H10-'минимумы и максимумы'!F$9)/('минимумы и максимумы'!F$10-'минимумы и максимумы'!F$9)*100) -> 37.931034 | I10: =IF('исходные данные'!I10>'минимумы и максимумы'!G$10,100,('исходные данные'!I10-'минимумы и максимумы'!G$9)/('минимумы и максимумы'!G$10-'минимумы и максимумы'!G$9)*100) -> 60.377358 | J10: =IF('исходные данные'!J10>'минимумы и максимумы'!H$10,100,('исходные данные'!J10-'минимумы и максимумы'!H$9)/('минимумы и максимумы'!H$10-'минимумы и максимумы'!H$9)*100) -> 46.666667 | K10: =IF('исходные данные'!K10>'минимумы и максимумы'!I$10,100,('исходные данные'!K10-'минимумы и максимумы'!I$9)/('минимумы и максимумы'!I$10-'минимумы и максимумы'!I$9)*100) -> 0 | ... U10: =IF('исходные данные'!U10>'минимумы и максимумы'!S$10,100,('исходные данные'!U10-'минимумы и максимумы'!S$9)/('минимумы и максимумы'!S$10-'минимумы и максимумы'!S$9)*100) -> 100
A11: 22 | B11: 0 | C11: 0 | D11: =IF('исходные данные'!D11>'минимумы и максимумы'!B$10,100,('исходные данные'!D11-'минимумы и максимумы'!B$9)/('минимумы и максимумы'!B$10-'минимумы и максимумы'!B$9)*100) -> 44.444444 | E11: =IF('исходные данные'!E11>'минимумы и максимумы'!C$10,100,('исходные данные'!E11-'минимумы и максимумы'!C$9)/('минимумы и максимумы'!C$10-'минимумы и максимумы'!C$9)*100) -> 60 | F11: =IF('исходные данные'!F11>'минимумы и максимумы'!D$10,100,('исходные данные'!F11-'минимумы и максимумы'!D$9)/('минимумы и максимумы'!D$10-'минимумы и максимумы'!D$9)*100) -> 0 | G11: =IF('исходные данные'!G11>'минимумы и максимумы'!E$10,100,('исходные данные'!G11-'минимумы и максимумы'!E$9)/('минимумы и максимумы'!E$10-'минимумы и максимумы'!E$9)*100) -> 20.833333 | H11: =IF('исходные данные'!H11>'минимумы и максимумы'!F$10,100,('исходные данные'!H11-'минимумы и максимумы'!F$9)/('минимумы и максимумы'!F$10-'минимумы и максимумы'!F$9)*100) -> 17.241379 | I11: =IF('исходные данные'!I11>'минимумы и максимумы'!G$10,100,('исходные данные'!I11-'минимумы и максимумы'!G$9)/('минимумы и максимумы'!G$10-'минимумы и максимумы'!G$9)*100) -> 30.188679 | J11: =IF('исходные данные'!J11>'минимумы и максимумы'!H$10,100,('исходные данные'!J11-'минимумы и максимумы'!H$9)/('минимумы и максимумы'!H$10-'минимумы и максимумы'!H$9)*100) -> 20 | K11: =IF('исходные данные'!K11>'минимумы и максимумы'!I$10,100,('исходные данные'!K11-'минимумы и максимумы'!I$9)/('минимумы и максимумы'!I$10-'минимумы и максимумы'!I$9)*100) -> 44.444444 | ... U11: =IF('исходные данные'!U11>'минимумы и максимумы'!S$10,100,('исходные данные'!U11-'минимумы и максимумы'!S$9)/('минимумы и максимумы'!S$10-'минимумы и максимумы'!S$9)*100) -> 0
A12: 27 | B12: 1 | C12: 0 | D12: =IF('исходные данные'!D12>'минимумы и максимумы'!B$10,100,('исходные данные'!D12-'минимумы и максимумы'!B$9)/('минимумы и максимумы'!B$10-'минимумы и максимумы'!B$9)*100) -> 44.444444 | E12: =IF('исходные данные'!E12>'минимумы и максимумы'!C$10,100,('исходные данные'!E12-'минимумы и максимумы'!C$9)/('минимумы и максимумы'!C$10-'минимумы и максимумы'!C$9)*100) -> 60 | F12: =IF('исходные данные'!F12>'минимумы и максимумы'!D$10,100,('исходные данные'!F12-'минимумы и максимумы'!D$9)/('минимумы и максимумы'!D$10-'минимумы и максимумы'!D$9)*100) -> 33.333333 | G12: =IF('исходные данные'!G12>'минимумы и максимумы'!E$10,100,('исходные данные'!G12-'минимумы и максимумы'!E$9)/('минимумы и максимумы'!E$10-'минимумы и максимумы'!E$9)*100) -> 83.333333 | H12: =IF('исходные данные'!H12>'минимумы и максимумы'!F$10,100,('исходные данные'!H12-'минимумы и максимумы'!F$9)/('минимумы и максимумы'!F$10-'минимумы и максимумы'!F$9)*100) -> 68.965517 | I12: =IF('исходные данные'!I12>'минимумы и максимумы'!G$10,100,('исходные данные'!I12-'минимумы и максимумы'!G$9)/('минимумы и максимумы'!G$10-'минимумы и максимумы'!G$9)*100) -> 84.90566 | J12: =IF('исходные данные'!J12>'минимумы и максимумы'!H$10,100,('исходные данные'!J12-'минимумы и максимумы'!H$9)/('минимумы и максимумы'!H$10-'минимумы и максимумы'!H$9)*100) -> 86.666667 | K12: =IF('исходные данные'!K12>'минимумы и максимумы'!I$10,100,('исходные данные'!K12-'минимумы и максимумы'!I$9)/('минимумы и максимумы'!I$10-'минимумы и максимумы'!I$9)*100) -> 27.777778 | ... U12: =IF('исходные данные'!U12>'минимумы и максимумы'!S$10,100,('исходные данные'!U12-'минимумы и максимумы'!S$9)/('минимумы и максимумы'!S$10-'минимумы и максимумы'!S$9)*100) -> 33.333333
A13: 29 | B13: 0 | C13: 0 | D13: =IF('исходные данные'!D13>'минимумы и максимумы'!B$10,100,('исходные данные'!D13-'минимумы и максимумы'!B$9)/('минимумы и максимумы'!B$10-'минимумы и максимумы'!B$9)*100) -> 77.777778 | E13: =IF('исходные данные'!E13>'минимумы и максимумы'!C$10,100,('исходные данные'!E13-'минимумы и максимумы'!C$9)/('минимумы и максимумы'!C$10-'минимумы и максимумы'!C$9)*100) -> 50 | F13: =IF('исходные данные'!F13>'минимумы и максимумы'!D$10,100,('исходные данные'!F13-'минимумы и максимумы'!D$9)/('минимумы и максимумы'!D$10-'минимумы и максимумы'!D$9)*100) -> 66.666667 | G13: =IF('исходные данные'!G13>'минимумы и максимумы'!E$10,100,('исходные данные'!G13-'минимумы и максимумы'!E$9)/('минимумы и максимумы'!E$10-'минимумы и максимумы'!E$9)*100) -> 58.333333 | H13: =IF('исходные данные'!H13>'минимумы и максимумы'!F$10,100,('исходные данные'!H13-'минимумы и максимумы'!F$9)/('минимумы и максимумы'!F$10-'минимумы и максимумы'!F$9)*100) -> 55.172414 | I13: =IF('исходные данные'!I13>'минимумы и максимумы'!G$10,100,('исходные данные'!I13-'минимумы и максимумы'!G$9)/('минимумы и максимумы'!G$10-'минимумы и максимумы'!G$9)*100) -> 94.339623 | J13: =IF('исходные данные'!J13>'минимумы и максимумы'!H$10,100,('исходные данные'!J13-'минимумы и максимумы'!H$9)/('минимумы и максимумы'!H$10-'минимумы и максимумы'!H$9)*100) -> 100 | K13: =IF('исходные данные'!K13>'минимумы и максимумы'!I$10,100,('исходные данные'!K13-'минимумы и максимумы'!I$9)/('минимумы и максимумы'!I$10-'минимумы и максимумы'!I$9)*100) -> 72.222222 | ... U13: =IF('исходные данные'!U13>'минимумы и максимумы'!S$10,100,('исходные данные'!U13-'минимумы и максимумы'!S$9)/('минимумы и максимумы'!S$10-'минимумы и максимумы'!S$9)*100) -> 66.666667
... A432: 553 | B432: 0 | C432: 0 | D432: =IF('исходные данные'!D432>'минимумы и максимумы'!B$10,100,('исходные данные'!D432-'минимумы и максимумы'!B$9)/('минимумы и максимумы'!B$10-'минимумы и максимумы'!B$9)*100) -> 0 | E432: =IF('исходные данные'!E432>'минимумы и максимумы'!C$10,100,('исходные данные'!E432-'минимумы и максимумы'!C$9)/('минимумы и максимумы'!C$10-'минимумы и максимумы'!C$9)*100) -> 0 | F432: =IF('исходные данные'!F432>'минимумы и максимумы'!D$10,100,('исходные данные'!F432-'минимумы и максимумы'!D$9)/('минимумы и максимумы'!D$10-'минимумы и максимумы'!D$9)*100) -> 0 | G432: =IF('исходные данные'!G432>'минимумы и максимумы'!E$10,100,('исходные данные'!G432-'минимумы и максимумы'!E$9)/('минимумы и максимумы'!E$10-'минимумы и максимумы'!E$9)*100) -> 0 | H432: =IF('исходные данные'!H432>'минимумы и максимумы'!F$10,100,('исходные данные'!H432-'минимумы и максимумы'!F$9)/('минимумы и максимумы'!F$10-'минимумы и максимумы'!F$9)*100) -> 0 | I432: =IF('исходные данные'!I432>'минимумы и максимумы'!G$10,100,('исходные данные'!I432-'минимумы и максимумы'!G$9)/('минимумы и максимумы'!G$10-'минимумы и максимумы'!G$9)*100) -> 3.7735849 | J432: =IF('исходные данные'!J432>'минимумы и максимумы'!H$10,100,('исходные данные'!J432-'минимумы и максимумы'!H$9)/('минимумы и максимумы'!H$10-'минимумы и максимумы'!H$9)*100) -> 0 | K432: =IF('исходные данные'!K432>'минимумы и максимумы'!I$10,100,('исходные данные'!K432-'минимумы и максимумы'!I$9)/('минимумы и максимумы'!I$10-'минимумы и максимумы'!I$9)*100) -> 0 | ... U432: =IF('исходные данные'!U432>'минимумы и максимумы'!S$10,100,('исходные данные'!U432-'минимумы и максимумы'!S$9)/('минимумы и максимумы'!S$10-'минимумы и максимумы'!S$9)*100) -> 66.666667

Sheet нормал с макс с К 1,5
A1: id | B1: vosstanovleno | C1: sneseno | D1: school | E1: kindergarten | F1: polyclinic | G1: supermarket | H1: PVZ | I1: obshepit | J1: hotel | K1: BC | L1: bank | M1: stop | N1: to_centre | O1: condition | P1: value | Q1: b_n | R1: zone | S1: floors | T1: s_base | U1: complexity
A2: 1 | B2: 0 | C2: 0 | D2: =IF('исходные данные'!D2>'минимумы и максимумы'!B$3,100,('исходные данные'!D2-'минимумы и максимумы'!B$2)/('минимумы и максимумы'!B$3-'минимумы и максимумы'!B$2)*100) -> 80 | E2: =IF('исходные данные'!E2>'минимумы и максимумы'!C$3,100,('исходные данные'!E2-'минимумы и максимумы'!C$2)/('минимумы и максимумы'!C$3-'минимумы и максимумы'!C$2)*100) -> 80 | F2: =IF('исходные данные'!F2>'минимумы и максимумы'!D$3,100,('исходные данные'!F2-'минимумы и максимумы'!D$2)/('минимумы и максимумы'!D$3-'минимумы и максимумы'!D$2)*100) -> 33.333333 | G2: =IF('исходные данные'!G2>'минимумы и максимумы'!E$3,100,('исходные данные'!G2-'минимумы и максимумы'!E$2)/('минимумы и максимумы'!E$3-'минимумы и максимумы'!E$2)*100) -> 66.666667 | H2: =IF('исходные данные'!H2>'минимумы и максимумы'!F$3,100,('исходные данные'!H2-'минимумы и максимумы'!F$2)/('минимумы и максимумы'!F$3-'минимумы и максимумы'!F$2)*100) -> 80 | I2: =IF('исходные данные'!I2>'минимумы и максимумы'!G$3,100,('исходные данные'!I2-'минимумы и максимумы'!G$2)/('минимумы и максимумы'!G$3-'минимумы и максимумы'!G$2)*100) -> 100 | J2: =IF('исходные данные'!J2>'минимумы и максимумы'!H$3,100,('исходные данные'!J2-'минимумы и максимумы'!H$2)/('минимумы и максимумы'!H$3-'минимумы и максимумы'!H$2)*100) -> 100 | K2: =IF('исходные данные'!K2>'минимумы и максимумы'!I$3,100,('исходные данные'!K2-'минимумы и максимумы'!I$2)/('минимумы и максимумы'!I$3-'минимумы и максимумы'!I$2)*100) -> 33.333333 | ... U2: =IF('исходные данные'!U2>'минимумы и максимумы'!S$3,100,('исходные данные'!U2-'минимумы и максимумы'!S$2)/('минимумы и максимумы'!S$3-'минимумы и максимумы'!S$2)*100) -> 100
A3: 2 | B3: 0 | C3: 0 | D3: =IF('исходные данные'!D3>'минимумы и максимумы'!B$3,100,('исходные данные'!D3-'минимумы и максимумы'!B$2)/('минимумы и максимумы'!B$3-'минимумы и максимумы'!B$2)*100) -> 0 | E3: =IF('исходные данные'!E3>'минимумы и максимумы'!C$3,100,('исходные данные'!E3-'минимумы и максимумы'!C$2)/('минимумы и максимумы'!C$3-'минимумы и максимумы'!C$2)*100) -> 0 | F3: =IF('исходные данные'!F3>'минимумы и максимумы'!D$3,100,('исходные данные'!F3-'минимумы и максимумы'!D$2)/('минимумы и максимумы'!D$3-'минимумы и максимумы'!D$2)*100) -> 0 | G3: =IF('исходные данные'!G3>'минимумы и максимумы'!E$3,100,('исходные данные'!G3-'минимумы и максимумы'!E$2)/('минимумы и максимумы'!E$3-'минимумы и максимумы'!E$2)*100) -> 0 | H3: =IF('исходные данные'!H3>'минимумы и максимумы'!F$3,100,('исходные данные'!H3-'минимумы и максимумы'!F$2)/('минимумы и максимумы'!F$3-'минимумы и максимумы'!F$2)*100) -> 0 | I3: =IF('исходные данные'!I3>'минимумы и максимумы'!G$3,100,('исходные данные'!I3-'минимумы и максимумы'!G$2)/('минимумы и максимумы'!G$3-'минимумы и максимумы'!G$2)*100) -> 1.8867925 | J3: =IF('исходные данные'!J3>'минимумы и максимумы'!H$3,100,('исходные данные'!J3-'минимумы и максимумы'!H$2)/('минимумы и максимумы'!H$3-'минимумы и максимумы'!H$2)*100) -> 0 | K3: =IF('исходные данные'!K3>'минимумы и максимумы'!I$3,100,('исходные данные'!K3-'минимумы и максимумы'!I$2)/('минимумы и максимумы'!I$3-'минимумы и максимумы'!I$2)*100) -> 5.5555556 | ... U3: =IF('исходные данные'!U3>'минимумы и максимумы'!S$3,100,('исходные данные'!U3-'минимумы и максимумы'!S$2)/('минимумы и максимумы'!S$3-'минимумы и максимумы'!S$2)*100) -> 33.333333
A4: 3 | B4: 0 | C4: 0 | D4: =IF('исходные данные'!D4>'минимумы и максимумы'!B$3,100,('исходные данные'!D4-'минимумы и максимумы'!B$2)/('минимумы и максимумы'!B$3-'минимумы и максимумы'!B$2)*100) -> 80 | E4: =IF('исходные данные'!E4>'минимумы и максимумы'!C$3,100,('исходные данные'!E4-'минимумы и максимумы'!C$2)/('минимумы и максимумы'!C$3-'минимумы и максимумы'!C$2)*100) -> 40 | F4: =IF('исходные данные'!F4>'минимумы и максимумы'!D$3,100,('исходные данные'!F4-'минимумы и максимумы'!D$2)/('минимумы и максимумы'!D$3-'минимумы и максимумы'!D$2)*100) -> 0 | G4: =IF('исходные данные'!G4>'минимумы и максимумы'!E$3,100,('исходные данные'!G4-'минимумы и максимумы'!E$2)/('минимумы и максимумы'!E$3-'минимумы и максимумы'!E$2)*100) -> 37.5 | H4: =IF('исходные данные'!H4>'минимумы и максимумы'!F$3,100,('исходные данные'!H4-'минимумы и максимумы'!F$2)/('минимумы и максимумы'!F$3-'минимумы и максимумы'!F$2)*100) -> 36 | I4: =IF('исходные данные'!I4>'минимумы и максимумы'!G$3,100,('исходные данные'!I4-'минимумы и максимумы'!G$2)/('минимумы и максимумы'!G$3-'минимумы и максимумы'!G$2)*100) -> 100 | J4: =IF('исходные данные'!J4>'минимумы и максимумы'!H$3,100,('исходные данные'!J4-'минимумы и максимумы'!H$2)/('минимумы и максимумы'!H$3-'минимумы и максимумы'!H$2)*100) -> 80 | K4: =IF('исходные данные'!K4>'минимумы и максимумы'!I$3,100,('исходные данные'!K4-'минимумы и максимумы'!I$2)/('минимумы и максимумы'!I$3-'минимумы и максимумы'!I$2)*100) -> 27.777778 | ... U4: =IF('исходные данные'!U4>'минимумы и максимумы'!S$3,100,('исходные данные'!U4-'минимумы и максимумы'!S$2)/('минимумы и максимумы'!S$3-'минимумы и максимумы'!S$2)*100) -> 33.333333
A5: 5 | B5: 0 | C5: 0 | D5: =IF('исходные данные'!D5>'минимумы и максимумы'!B$3,100,('исходные данные'!D5-'минимумы и максимумы'!B$2)/('минимумы и максимумы'!B$3-'минимумы и максимумы'!B$2)*100) -> 40 | E5: =IF('исходные данные'!E5>'минимумы и максимумы'!C$3,100,('исходные данные'!E5-'минимумы и максимумы'!C$2)/('минимумы и максимумы'!C$3-'минимумы и максимумы'!C$2)*100) -> 70 | F5: =IF('исходные данные'!F5>'минимумы и максимумы'!D$3,100,('исходные данные'!F5-'минимумы и максимумы'!D$2)/('минимумы и максимумы'!D$3-'минимумы и максимумы'!D$2)*100) -> 0 | G5: =IF('исходные данные'!G5>'минимумы и максимумы'!E$3,100,('исходные данные'!G5-'минимумы и максимумы'!E$2)/('минимумы и максимумы'!E$3-'минимумы и максимумы'!E$2)*100) -> 25 | H5: =IF('исходные данные'!H5>'минимумы и максимумы'!F$3,100,('исходные данные'!H5-'минимумы и максимумы'!F$2)/('минимумы и максимумы'!F$3-'минимумы и максимумы'!F$2)*100) -> 20 | I5: =IF('исходные данные'!I5>'минимумы и максимумы'!G$3,100,('исходные данные'!I5-'минимумы и максимумы'!G$2)/('минимумы и максимумы'!G$3-'минимумы и максимумы'!G$2)*100) -> 100 | J5: =IF('исходные данные'!J5>'минимумы и максимумы'!H$3,100,('исходные данные'!J5-'минимумы и максимумы'!H$2)/('минимумы и максимумы'!H$3-'минимумы и максимумы'!H$2)*100) -> 46.666667 | K5: =IF('исходные данные'!K5>'минимумы и максимумы'!I$3,100,('исходные данные'!K5-'минимумы и максимумы'!I$2)/('минимумы и максимумы'!I$3-'минимумы и максимумы'!I$2)*100) -> 5.5555556 | ... U5: =IF('исходные данные'!U5>'минимумы и максимумы'!S$3,100,('исходные данные'!U5-'минимумы и максимумы'!S$2)/('минимумы и максимумы'!S$3-'минимумы и максимумы'!S$2)*100) -> 66.666667
A6: 6 | B6: 0 | C6: 0 | D6: =IF('исходные данные'!D6>'минимумы и максимумы'!B$3,100,('исходные данные'!D6-'минимумы и максимумы'!B$2)/('минимумы и максимумы'!B$3-'минимумы и максимумы'!B$2)*100) -> 80 | E6: =IF('исходные данные'!E6>'минимумы и максимумы'!C$3,100,('исходные данные'!E6-'минимумы и максимумы'!C$2)/('минимумы и максимумы'!C$3-'минимумы и максимумы'!C$2)*100) -> 60 | F6: =IF('исходные данные'!F6>'минимумы и максимумы'!D$3,100,('исходные данные'!F6-'минимумы и максимумы'!D$2)/('минимумы и максимумы'!D$3-'минимумы и максимумы'!D$2)*100) -> 0 | G6: =IF('исходные данные'!G6>'минимумы и максимумы'!E$3,100,('исходные данные'!G6-'минимумы и максимумы'!E$2)/('минимумы и максимумы'!E$3-'минимумы и максимумы'!E$2)*100) -> 20.833333 | H6: =IF('исходные данные'!H6>'минимумы и максимумы'!F$3,100,('исходные данные'!H6-'минимумы и максимумы'!F$2)/('минимумы и максимумы'!F$3-'минимумы и максимумы'!F$2)*100) -> 20 | I6: =IF('исходные данные'!I6>'минимумы и максимумы'!G$3,100,('исходные данные'!I6-'минимумы и максимумы'!G$2)/('минимумы и максимумы'!G$3-'минимумы и максимумы'!G$2)*100) -> 100 | J6: =IF('исходные данные'!J6>'минимумы и максимумы'!H$3,100,('исходные данные'!J6-'минимумы и максимумы'!H$2)/('минимумы и максимумы'!H$3-'минимумы и максимумы'!H$2)*100) -> 60 | K6: =IF('исходные данные'!K6>'минимумы и максимумы'!I$3,100,('исходные данные'!K6-'минимумы и максимумы'!I$2)/('минимумы и максимумы'!I$3-'минимумы и максимумы'!I$2)*100) -> 5.5555556 | ... U6: =IF('исходные данные'!U6>'минимумы и максимумы'!S$3,100,('исходные данные'!U6-'минимумы и максимумы'!S$2)/('минимумы и максимумы'!S$3-'минимумы и максимумы'!S$2)*100) -> 100
A7: 7 | B7: 0 | C7: 0 | D7: =IF('исходные данные'!D7>'минимумы и максимумы'!B$3,100,('исходные данные'!D7-'минимумы и максимумы'!B$2)/('минимумы и максимумы'!B$3-'минимумы и максимумы'!B$2)*100) -> 80 | E7: =IF('исходные данные'!E7>'минимумы и максимумы'!C$3,100,('исходные данные'!E7-'минимумы и максимумы'!C$2)/('минимумы и максимумы'!C$3-'минимумы и максимумы'!C$2)*100) -> 60 | F7: =IF('исходные данные'!F7>'минимумы и максимумы'!D$3,100,('исходные данные'!F7-'минимумы и максимумы'!D$2)/('минимумы и максимумы'!D$3-'минимумы и максимумы'!D$2)*100) -> 0 | G7: =IF('исходные данные'!G7>'минимумы и максимумы'!E$3,100,('исходные данные'!G7-'минимумы и максимумы'!E$2)/('минимумы и максимумы'!E$3-'минимумы и максимумы'!E$2)*100) -> 29.166667 | H7: =IF('исходные данные'!H7>'минимумы и максимумы'!F$3,100,('исходные данные'!H7-'минимумы и максимумы'!F$2)/('минимумы и максимумы'!F$3-'минимумы и максимумы'!F$2)*100) -> 36 | I7: =IF('исходные данные'!I7>'минимумы и максимумы'!G$3,100,('исходные данные'!I7-'минимумы и максимумы'!G$2)/('минимумы и максимумы'!G$3-'минимумы и максимумы'!G$2)*100) -> 100 | J7: =IF('исходные данные'!J7>'минимумы и максимумы'!H$3,100,('исходные данные'!J7-'минимумы и максимумы'!H$2)/('минимумы и максимумы'!H$3-'минимумы и максимумы'!H$2)*100) -> 86.666667 | K7: =IF('исходные данные'!K7>'минимумы и максимумы'!I$3,100,('исходные данные'!K7-'минимумы и максимумы'!I$2)/('минимумы и максимумы'!I$3-'минимумы и максимумы'!I$2)*100) -> 22.222222 | ... U7: =IF('исходные данные'!U7>'минимумы и максимумы'!S$3,100,('исходные данные'!U7-'минимумы и максимумы'!S$2)/('минимумы и максимумы'!S$3-'минимумы и максимумы'!S$2)*100) -> 100
A8: 17 | B8: 0 | C8: 0 | D8: =IF('исходные данные'!D8>'минимумы и максимумы'!B$3,100,('исходные данные'!D8-'минимумы и максимумы'!B$2)/('минимумы и максимумы'!B$3-'минимумы и максимумы'!B$2)*100) -> 0 | E8: =IF('исходные данные'!E8>'минимумы и максимумы'!C$3,100,('исходные данные'!E8-'минимумы и максимумы'!C$2)/('минимумы и максимумы'!C$3-'минимумы и максимумы'!C$2)*100) -> 0 | F8: =IF('исходные данные'!F8>'минимумы и максимумы'!D$3,100,('исходные данные'!F8-'минимумы и максимумы'!D$2)/('минимумы и максимумы'!D$3-'минимумы и максимумы'!D$2)*100) -> 0 | G8: =IF('исходные данные'!G8>'минимумы и максимумы'!E$3,100,('исходные данные'!G8-'минимумы и максимумы'!E$2)/('минимумы и максимумы'!E$3-'минимумы и максимумы'!E$2)*100) -> 12.5 | H8: =IF('исходные данные'!H8>'минимумы и максимумы'!F$3,100,('исходные данные'!H8-'минимумы и максимумы'!F$2)/('минимумы и максимумы'!F$3-'минимумы и максимумы'!F$2)*100) -> 8 | I8: =IF('исходные данные'!I8>'минимумы и максимумы'!G$3,100,('исходные данные'!I8-'минимумы и максимумы'!G$2)/('минимумы и максимумы'!G$3-'минимумы и максимумы'!G$2)*100) -> 67.924528 | J8: =IF('исходные данные'!J8>'минимумы и максимумы'!H$3,100,('исходные данные'!J8-'минимумы и максимумы'!H$2)/('минимумы и максимумы'!H$3-'минимумы и максимумы'!H$2)*100) -> 6.6666667 | K8: =IF('исходные данные'!K8>'минимумы и максимумы'!I$3,100,('исходные данные'!K8-'минимумы и максимумы'!I$2)/('минимумы и максимумы'!I$3-'минимумы и максимумы'!I$2)*100) -> 0 | ... U8: =IF('исходные данные'!U8>'минимумы и максимумы'!S$3,100,('исходные данные'!U8-'минимумы и максимумы'!S$2)/('минимумы и максимумы'!S$3-'минимумы и максимумы'!S$2)*100) -> 0
A9: 20 | B9: 0 | C9: 0 | D9: =IF('исходные данные'!D9>'минимумы и максимумы'!B$3,100,('исходные данные'!D9-'минимумы и максимумы'!B$2)/('минимумы и максимумы'!B$3-'минимумы и максимумы'!B$2)*100) -> 20 | E9: =IF('исходные данные'!E9>'минимумы и максимумы'!C$3,100,('исходные данные'!E9-'минимумы и максимумы'!C$2)/('минимумы и максимумы'!C$3-'минимумы и максимумы'!C$2)*100) -> 10 | F9: =IF('исходные данные'!F9>'минимумы и максимумы'!D$3,100,('исходные данные'!F9-'минимумы и максимумы'!D$2)/('минимумы и максимумы'!D$3-'минимумы и максимумы'!D$2)*100) -> 33.333333 | G9: =IF('исходные данные'!G9>'минимумы и максимумы'!E$3,100,('исходные данные'!G9-'минимумы и максимумы'!E$2)/('минимумы и максимумы'!E$3-'минимумы и максимумы'!E$2)*100) -> 37.5 | H9: =IF('исходные данные'!H9>'минимумы и максимумы'!F$3,100,('исходные данные'!H9-'минимумы и максимумы'!F$2)/('минимумы и максимумы'!F$3-'минимумы и максимумы'!F$2)*100) -> 32 | I9: =IF('исходные данные'!I9>'минимумы и максимумы'!G$3,100,('исходные данные'!I9-'минимумы и максимумы'!G$2)/('минимумы и максимумы'!G$3-'минимумы и максимумы'!G$2)*100) -> 35.849057 | J9: =IF('исходные данные'!J9>'минимумы и максимумы'!H$3,100,('исходные данные'!J9-'минимумы и максимумы'!H$2)/('минимумы и максимумы'!H$3-'минимумы и максимумы'!H$2)*100) -> 60 | K9: =IF('исходные данные'!K9>'минимумы и максимумы'!I$3,100,('исходные данные'!K9-'минимумы и максимумы'!I$2)/('минимумы и максимумы'!I$3-'минимумы и максимумы'!I$2)*100) -> 72.222222 | ... U9: =IF('исходные данные'!U9>'минимумы и максимумы'!S$3,100,('исходные данные'!U9-'минимумы и максимумы'!S$2)/('минимумы и максимумы'!S$3-'минимумы и максимумы'!S$2)*100) -> 66.666667
A10: 21 | B10: 0 | C10: 1 | D10: =IF('исходные данные'!D10>'минимумы и максимумы'!B$3,100,('исходные данные'!D10-'минимумы и максимумы'!B$2)/('минимумы и максимумы'!B$3-'минимумы и максимумы'!B$2)*100) -> 20 | E10: =IF('исходные данные'!E10>'минимумы и максимумы'!C$3,100,('исходные данные'!E10-'минимумы и максимумы'!C$2)/('минимумы и максимумы'!C$3-'минимумы и максимумы'!C$2)*100) -> 30 | F10: =IF('исходные данные'!F10>'минимумы и максимумы'!D$3,100,('исходные данные'!F10-'минимумы и максимумы'!D$2)/('минимумы и максимумы'!D$3-'минимумы и максимумы'!D$2)*100) -> 0 | G10: =IF('исходные данные'!G10>'минимумы и максимумы'!E$3,100,('исходные данные'!G10-'минимумы и максимумы'!E$2)/('минимумы и максимумы'!E$3-'минимумы и максимумы'!E$2)*100) -> 37.5 | H10: =IF('исходные данные'!H10>'минимумы и максимумы'!F$3,100,('исходные данные'!H10-'минимумы и максимумы'!F$2)/('минимумы и максимумы'!F$3-'минимумы и максимумы'!F$2)*100) -> 44 | I10: =IF('исходные данные'!I10>'минимумы и максимумы'!G$3,100,('исходные данные'!I10-'минимумы и максимумы'!G$2)/('минимумы и максимумы'!G$3-'минимумы и максимумы'!G$2)*100) -> 60.377358 | J10: =IF('исходные данные'!J10>'минимумы и максимумы'!H$3,100,('исходные данные'!J10-'минимумы и максимумы'!H$2)/('минимумы и максимумы'!H$3-'минимумы и максимумы'!H$2)*100) -> 46.666667 | K10: =IF('исходные данные'!K10>'минимумы и максимумы'!I$3,100,('исходные данные'!K10-'минимумы и максимумы'!I$2)/('минимумы и максимумы'!I$3-'минимумы и максимумы'!I$2)*100) -> 0 | ... U10: =IF('исходные данные'!U10>'минимумы и максимумы'!S$3,100,('исходные данные'!U10-'минимумы и максимумы'!S$2)/('минимумы и максимумы'!S$3-'минимумы и максимумы'!S$2)*100) -> 100
A11: 22 | B11: 0 | C11: 0 | D11: =IF('исходные данные'!D11>'минимумы и максимумы'!B$3,100,('исходные данные'!D11-'минимумы и максимумы'!B$2)/('минимумы и максимумы'!B$3-'минимумы и максимумы'!B$2)*100) -> 80 | E11: =IF('исходные данные'!E11>'минимумы и максимумы'!C$3,100,('исходные данные'!E11-'минимумы и максимумы'!C$2)/('минимумы и максимумы'!C$3-'минимумы и максимумы'!C$2)*100) -> 60 | F11: =IF('исходные данные'!F11>'минимумы и максимумы'!D$3,100,('исходные данные'!F11-'минимумы и максимумы'!D$2)/('минимумы и максимумы'!D$3-'минимумы и максимумы'!D$2)*100) -> 0 | G11: =IF('исходные данные'!G11>'минимумы и максимумы'!E$3,100,('исходные данные'!G11-'минимумы и максимумы'!E$2)/('минимумы и максимумы'!E$3-'минимумы и максимумы'!E$2)*100) -> 20.833333 | H11: =IF('исходные данные'!H11>'минимумы и максимумы'!F$3,100,('исходные данные'!H11-'минимумы и максимумы'!F$2)/('минимумы и максимумы'!F$3-'минимумы и максимумы'!F$2)*100) -> 20 | I11: =IF('исходные данные'!I11>'минимумы и максимумы'!G$3,100,('исходные данные'!I11-'минимумы и максимумы'!G$2)/('минимумы и максимумы'!G$3-'минимумы и максимумы'!G$2)*100) -> 30.188679 | J11: =IF('исходные данные'!J11>'минимумы и максимумы'!H$3,100,('исходные данные'!J11-'минимумы и максимумы'!H$2)/('минимумы и максимумы'!H$3-'минимумы и максимумы'!H$2)*100) -> 20 | K11: =IF('исходные данные'!K11>'минимумы и максимумы'!I$3,100,('исходные данные'!K11-'минимумы и максимумы'!I$2)/('минимумы и максимумы'!I$3-'минимумы и максимумы'!I$2)*100) -> 44.444444 | ... U11: =IF('исходные данные'!U11>'минимумы и максимумы'!S$3,100,('исходные данные'!U11-'минимумы и максимумы'!S$2)/('минимумы и максимумы'!S$3-'минимумы и максимумы'!S$2)*100) -> 0
A12: 27 | B12: 1 | C12: 0 | D12: =IF('исходные данные'!D12>'минимумы и максимумы'!B$3,100,('исходные данные'!D12-'минимумы и максимумы'!B$2)/('минимумы и максимумы'!B$3-'минимумы и максимумы'!B$2)*100) -> 80 | E12: =IF('исходные данные'!E12>'минимумы и максимумы'!C$3,100,('исходные данные'!E12-'минимумы и максимумы'!C$2)/('минимумы и максимумы'!C$3-'минимумы и максимумы'!C$2)*100) -> 60 | F12: =IF('исходные данные'!F12>'минимумы и максимумы'!D$3,100,('исходные данные'!F12-'минимумы и максимумы'!D$2)/('минимумы и максимумы'!D$3-'минимумы и максимумы'!D$2)*100) -> 33.333333 | G12: =IF('исходные данные'!G12>'минимумы и максимумы'!E$3,100,('исходные данные'!G12-'минимумы и максимумы'!E$2)/('минимумы и максимумы'!E$3-'минимумы и максимумы'!E$2)*100) -> 83.333333 | H12: =IF('исходные данные'!H12>'минимумы и максимумы'!F$3,100,('исходные данные'!H12-'минимумы и максимумы'!F$2)/('минимумы и максимумы'!F$3-'минимумы и максимумы'!F$2)*100) -> 80 | I12: =IF('исходные данные'!I12>'минимумы и максимумы'!G$3,100,('исходные данные'!I12-'минимумы и максимумы'!G$2)/('минимумы и максимумы'!G$3-'минимумы и максимумы'!G$2)*100) -> 84.90566 | J12: =IF('исходные данные'!J12>'минимумы и максимумы'!H$3,100,('исходные данные'!J12-'минимумы и максимумы'!H$2)/('минимумы и максимумы'!H$3-'минимумы и максимумы'!H$2)*100) -> 86.666667 | K12: =IF('исходные данные'!K12>'минимумы и максимумы'!I$3,100,('исходные данные'!K12-'минимумы и максимумы'!I$2)/('минимумы и максимумы'!I$3-'минимумы и максимумы'!I$2)*100) -> 27.777778 | ... U12: =IF('исходные данные'!U12>'минимумы и максимумы'!S$3,100,('исходные данные'!U12-'минимумы и максимумы'!S$2)/('минимумы и максимумы'!S$3-'минимумы и максимумы'!S$2)*100) -> 33.333333
A13: 29 | B13: 0 | C13: 0 | D13: =IF('исходные данные'!D13>'минимумы и максимумы'!B$3,100,('исходные данные'!D13-'минимумы и максимумы'!B$2)/('минимумы и максимумы'!B$3-'минимумы и максимумы'!B$2)*100) -> 100 | E13: =IF('исходные данные'!E13>'минимумы и максимумы'!C$3,100,('исходные данные'!E13-'минимумы и максимумы'!C$2)/('минимумы и максимумы'!C$3-'минимумы и максимумы'!C$2)*100) -> 50 | F13: =IF('исходные данные'!F13>'минимумы и максимумы'!D$3,100,('исходные данные'!F13-'минимумы и максимумы'!D$2)/('минимумы и максимумы'!D$3-'минимумы и максимумы'!D$2)*100) -> 66.666667 | G13: =IF('исходные данные'!G13>'минимумы и максимумы'!E$3,100,('исходные данные'!G13-'минимумы и максимумы'!E$2)/('минимумы и максимумы'!E$3-'минимумы и максимумы'!E$2)*100) -> 58.333333 | H13: =IF('исходные данные'!H13>'минимумы и максимумы'!F$3,100,('исходные данные'!H13-'минимумы и максимумы'!F$2)/('минимумы и максимумы'!F$3-'минимумы и максимумы'!F$2)*100) -> 64 | I13: =IF('исходные данные'!I13>'минимумы и максимумы'!G$3,100,('исходные данные'!I13-'минимумы и максимумы'!G$2)/('минимумы и максимумы'!G$3-'минимумы и максимумы'!G$2)*100) -> 94.339623 | J13: =IF('исходные данные'!J13>'минимумы и максимумы'!H$3,100,('исходные данные'!J13-'минимумы и максимумы'!H$2)/('минимумы и максимумы'!H$3-'минимумы и максимумы'!H$2)*100) -> 100 | K13: =IF('исходные данные'!K13>'минимумы и максимумы'!I$3,100,('исходные данные'!K13-'минимумы и максимумы'!I$2)/('минимумы и максимумы'!I$3-'минимумы и максимумы'!I$2)*100) -> 72.222222 | ... U13: =IF('исходные данные'!U13>'минимумы и максимумы'!S$3,100,('исходные данные'!U13-'минимумы и максимумы'!S$2)/('минимумы и максимумы'!S$3-'минимумы и максимумы'!S$2)*100) -> 66.666667
... A432: 553 | B432: 0 | C432: 0 | D432: =IF('исходные данные'!D432>'минимумы и максимумы'!B$3,100,('исходные данные'!D432-'минимумы и максимумы'!B$2)/('минимумы и максимумы'!B$3-'минимумы и максимумы'!B$2)*100) -> 0 | E432: =IF('исходные данные'!E432>'минимумы и максимумы'!C$3,100,('исходные данные'!E432-'минимумы и максимумы'!C$2)/('минимумы и максимумы'!C$3-'минимумы и максимумы'!C$2)*100) -> 0 | F432: =IF('исходные данные'!F432>'минимумы и максимумы'!D$3,100,('исходные данные'!F432-'минимумы и максимумы'!D$2)/('минимумы и максимумы'!D$3-'минимумы и максимумы'!D$2)*100) -> 0 | G432: =IF('исходные данные'!G432>'минимумы и максимумы'!E$3,100,('исходные данные'!G432-'минимумы и максимумы'!E$2)/('минимумы и максимумы'!E$3-'минимумы и максимумы'!E$2)*100) -> 0 | H432: =IF('исходные данные'!H432>'минимумы и максимумы'!F$3,100,('исходные данные'!H432-'минимумы и максимумы'!F$2)/('минимумы и максимумы'!F$3-'минимумы и максимумы'!F$2)*100) -> 0 | I432: =IF('исходные данные'!I432>'минимумы и максимумы'!G$3,100,('исходные данные'!I432-'минимумы и максимумы'!G$2)/('минимумы и максимумы'!G$3-'минимумы и максимумы'!G$2)*100) -> 3.7735849 | J432: =IF('исходные данные'!J432>'минимумы и максимумы'!H$3,100,('исходные данные'!J432-'минимумы и максимумы'!H$2)/('минимумы и максимумы'!H$3-'минимумы и максимумы'!H$2)*100) -> 0 | K432: =IF('исходные данные'!K432>'минимумы и максимумы'!I$3,100,('исходные данные'!K432-'минимумы и максимумы'!I$2)/('минимумы и максимумы'!I$3-'минимумы и максимумы'!I$2)*100) -> 0 | ... U432: =IF('исходные данные'!U432>'минимумы и максимумы'!S$3,100,('исходные данные'!U432-'минимумы и максимумы'!S$2)/('минимумы и максимумы'!S$3-'минимумы и максимумы'!S$2)*100) -> 66.666667

Sheet нормал с макс с К 3
A1: id | B1: vosstanovleno | C1: sneseno | D1: school | E1: kindergarten | F1: polyclinic | G1: supermarket | H1: PVZ | I1: obshepit | J1: hotel | K1: BC | L1: bank | M1: stop | N1: to_centre | O1: condition | P1: value | Q1: b_n | R1: zone | S1: floors | T1: s_base | U1: complexity
A2: 1 | B2: 0 | C2: 0 | D2: =IF('исходные данные'!D2>'минимумы и максимумы'!B$4,100,('исходные данные'!D2-'минимумы и максимумы'!B$2)/('минимумы и максимумы'!B$4-'минимумы и максимумы'!B$2)*100) -> 50 | E2: =IF('исходные данные'!E2>'минимумы и максимумы'!C$4,100,('исходные данные'!E2-'минимумы и максимумы'!C$2)/('минимумы и максимумы'!C$4-'минимумы и максимумы'!C$2)*100) -> 50 | F2: =IF('исходные данные'!F2>'минимумы и максимумы'!D$4,100,('исходные данные'!F2-'минимумы и максимумы'!D$2)/('минимумы и максимумы'!D$4-'минимумы и максимумы'!D$2)*100) -> 25 | G2: =IF('исходные данные'!G2>'минимумы и максимумы'!E$4,100,('исходные данные'!G2-'минимумы и максимумы'!E$2)/('минимумы и максимумы'!E$4-'минимумы и максимумы'!E$2)*100) -> 43.243243 | H2: =IF('исходные данные'!H2>'минимумы и максимумы'!F$4,100,('исходные данные'!H2-'минимумы и максимумы'!F$2)/('минимумы и максимумы'!F$4-'минимумы и максимумы'!F$2)*100) -> 52.631579 | I2: =IF('исходные данные'!I2>'минимумы и максимумы'!G$4,100,('исходные данные'!I2-'минимумы и максимумы'!G$2)/('минимумы и максимумы'!G$4-'минимумы и максимумы'!G$2)*100) -> 75.903614 | J2: =IF('исходные данные'!J2>'минимумы и максимумы'!H$4,100,('исходные данные'!J2-'минимумы и максимумы'!H$2)/('минимумы и максимумы'!H$4-'минимумы и максимумы'!H$2)*100) -> 91.666667 | K2: =IF('исходные данные'!K2>'минимумы и максимумы'!I$4,100,('исходные данные'!K2-'минимумы и максимумы'!I$2)/('минимумы и максимумы'!I$4-'минимумы и максимумы'!I$2)*100) -> 21.428571 | ... U2: =IF('исходные данные'!U2>'минимумы и максимумы'!S$4,100,('исходные данные'!U2-'минимумы и максимумы'!S$2)/('минимумы и максимумы'!S$4-'минимумы и максимумы'!S$2)*100) -> 100
A3: 2 | B3: 0 | C3: 0 | D3: =IF('исходные данные'!D3>'минимумы и максимумы'!B$4,100,('исходные данные'!D3-'минимумы и максимумы'!B$2)/('минимумы и максимумы'!B$4-'минимумы и максимумы'!B$2)*100) -> 0 | E3: =IF('исходные данные'!E3>'минимумы и максимумы'!C$4,100,('исходные данные'!E3-'минимумы и максимумы'!C$2)/('минимумы и максимумы'!C$4-'минимумы и максимумы'!C$2)*100) -> 0 | F3: =IF('исходные данные'!F3>'минимумы и максимумы'!D$4,100,('исходные данные'!F3-'минимумы и максимумы'!D$2)/('минимумы и максимумы'!D$4-'минимумы и максимумы'!D$2)*100) -> 0 | G3: =IF('исходные данные'!G3>'минимумы и максимумы'!E$4,100,('исходные данные'!G3-'минимумы и максимумы'!E$2)/('минимумы и максимумы'!E$4-'минимумы и максимумы'!E$2)*100) -> 0 | H3: =IF('исходные данные'!H3>'минимумы и максимумы'!F$4,100,('исходные данные'!H3-'минимумы и максимумы'!F$2)/('минимумы и максимумы'!F$4-'минимумы и максимумы'!F$2)*100) -> 0 | I3: =IF('исходные данные'!I3>'минимумы и максимумы'!G$4,100,('исходные данные'!I3-'минимумы и максимумы'!G$2)/('минимумы и максимумы'!G$4-'минимумы и максимумы'!G$2)*100) -> 1.2048193 | J3: =IF('исходные данные'!J3>'минимумы и максимумы'!H$4,100,('исходные данные'!J3-'минимумы и максимумы'!H$2)/('минимумы и максимумы'!H$4-'минимумы и максимумы'!H$2)*100) -> 0 | K3: =IF('исходные данные'!K3>'минимумы и максимумы'!I$4,100,('исходные данные'!K3-'минимумы и максимумы'!I$2)/('минимумы и максимумы'!I$4-'минимумы и максимумы'!I$2)*100) -> 3.5714286 | ... U3: =IF('исходные данные'!U3>'минимумы и максимумы'!S$4,100,('исходные данные'!U3-'минимумы и максимумы'!S$2)/('минимумы и максимумы'!S$4-'минимумы и максимумы'!S$2)*100) -> 33.333333
A4: 3 | B4: 0 | C4: 0 | D4: =IF('исходные данные'!D4>'минимумы и максимумы'!B$4,100,('исходные данные'!D4-'минимумы и максимумы'!B$2)/('минимумы и максимумы'!B$4-'минимумы и максимумы'!B$2)*100) -> 50 | E4: =IF('исходные данные'!E4>'минимумы и максимумы'!C$4,100,('исходные данные'!E4-'минимумы и максимумы'!C$2)/('минимумы и максимумы'!C$4-'минимумы и максимумы'!C$2)*100) -> 25 | F4: =IF('исходные данные'!F4>'минимумы и максимумы'!D$4,100,('исходные данные'!F4-'минимумы и максимумы'!D$2)/('минимумы и максимумы'!D$4-'минимумы и максимумы'!D$2)*100) -> 0 | G4: =IF('исходные данные'!G4>'минимумы и максимумы'!E$4,100,('исходные данные'!G4-'минимумы и максимумы'!E$2)/('минимумы и максимумы'!E$4-'минимумы и максимумы'!E$2)*100) -> 24.324324 | H4: =IF('исходные данные'!H4>'минимумы и максимумы'!F$4,100,('исходные данные'!H4-'минимумы и максимумы'!F$2)/('минимумы и максимумы'!F$4-'минимумы и максимумы'!F$2)*100) -> 23.684211 | I4: =IF('исходные данные'!I4>'минимумы и максимумы'!G$4,100,('исходные данные'!I4-'минимумы и максимумы'!G$2)/('минимумы и максимумы'!G$4-'минимумы и максимумы'!G$2)*100) -> 63.855422 | J4: =IF('исходные данные'!J4>'минимумы и максимумы'!H$4,100,('исходные данные'!J4-'минимумы и максимумы'!H$2)/('минимумы и максимумы'!H$4-'минимумы и максимумы'!H$2)*100) -> 50 | K4: =IF('исходные данные'!K4>'минимумы и максимумы'!I$4,100,('исходные данные'!K4-'минимумы и максимумы'!I$2)/('минимумы и максимумы'!I$4-'минимумы и максимумы'!I$2)*100) -> 17.857143 | ... U4: =IF('исходные данные'!U4>'минимумы и максимумы'!S$4,100,('исходные данные'!U4-'минимумы и максимумы'!S$2)/('минимумы и максимумы'!S$4-'минимумы и максимумы'!S$2)*100) -> 33.333333
A5: 5 | B5: 0 | C5: 0 | D5: =IF('исходные данные'!D5>'минимумы и максимумы'!B$4,100,('исходные данные'!D5-'минимумы и максимумы'!B$2)/('минимумы и максимумы'!B$4-'минимумы и максимумы'!B$2)*100) -> 25 | E5: =IF('исходные данные'!E5>'минимумы и максимумы'!C$4,100,('исходные данные'!E5-'минимумы и максимумы'!C$2)/('минимумы и максимумы'!C$4-'минимумы и максимумы'!C$2)*100) -> 43.75 | F5: =IF('исходные данные'!F5>'минимумы и максимумы'!D$4,100,('исходные данные'!F5-'минимумы и максимумы'!D$2)/('минимумы и максимумы'!D$4-'минимумы и максимумы'!D$2)*100) -> 0 | G5: =IF('исходные данные'!G5>'минимумы и максимумы'!E$4,100,('исходные данные'!G5-'минимумы и максимумы'!E$2)/('минимумы и максимумы'!E$4-'минимумы и максимумы'!E$2)*100) -> 16.216216 | H5: =IF('исходные данные'!H5>'минимумы и максимумы'!F$4,100,('исходные данные'!H5-'минимумы и максимумы'!F$2)/('минимумы и максимумы'!F$4-'минимумы и максимумы'!F$2)*100) -> 13.157895 | I5: =IF('исходные данные'!I5>'минимумы и максимумы'!G$4,100,('исходные данные'!I5-'минимумы и максимумы'!G$2)/('минимумы и максимумы'!G$4-'минимумы и максимумы'!G$2)*100) -> 66.26506 | J5: =IF('исходные данные'!J5>'минимумы и максимумы'!H$4,100,('исходные данные'!J5-'минимумы и максимумы'!H$2)/('минимумы и максимумы'!H$4-'минимумы и максимумы'!H$2)*100) -> 29.166667 | K5: =IF('исходные данные'!K5>'минимумы и максимумы'!I$4,100,('исходные данные'!K5-'минимумы и максимумы'!I$2)/('минимумы и максимумы'!I$4-'минимумы и максимумы'!I$2)*100) -> 3.5714286 | ... U5: =IF('исходные данные'!U5>'минимумы и максимумы'!S$4,100,('исходные данные'!U5-'минимумы и максимумы'!S$2)/('минимумы и максимумы'!S$4-'минимумы и максимумы'!S$2)*100) -> 66.666667
A6: 6 | B6: 0 | C6: 0 | D6: =IF('исходные данные'!D6>'минимумы и максимумы'!B$4,100,('исходные данные'!D6-'минимумы и максимумы'!B$2)/('минимумы и максимумы'!B$4-'минимумы и максимумы'!B$2)*100) -> 50 | E6: =IF('исходные данные'!E6>'минимумы и максимумы'!C$4,100,('исходные данные'!E6-'минимумы и максимумы'!C$2)/('минимумы и максимумы'!C$4-'минимумы и максимумы'!C$2)*100) -> 37.5 | F6: =IF('исходные данные'!F6>'минимумы и максимумы'!D$4,100,('исходные данные'!F6-'минимумы и максимумы'!D$2)/('минимумы и максимумы'!D$4-'минимумы и максимумы'!D$2)*100) -> 0 | G6: =IF('исходные данные'!G6>'минимумы и максимумы'!E$4,100,('исходные данные'!G6-'минимумы и максимумы'!E$2)/('минимумы и максимумы'!E$4-'минимумы и максимумы'!E$2)*100) -> 13.513514 | H6: =IF('исходные данные'!H6>'минимумы и максимумы'!F$4,100,('исходные данные'!H6-'минимумы и максимумы'!F$2)/('минимумы и максимумы'!F$4-'минимумы и максимумы'!F$2)*100) -> 13.157895 | I6: =IF('исходные данные'!I6>'минимумы и максимумы'!G$4,100,('исходные данные'!I6-'минимумы и максимумы'!G$2)/('минимумы и максимумы'!G$4-'минимумы и максимумы'!G$2)*100) -> 65.060241 | J6: =IF('исходные данные'!J6>'минимумы и максимумы'!H$4,100,('исходные данные'!J6-'минимумы и максимумы'!H$2)/('минимумы и максимумы'!H$4-'минимумы и максимумы'!H$2)*100) -> 37.5 | K6: =IF('исходные данные'!K6>'минимумы и максимумы'!I$4,100,('исходные данные'!K6-'минимумы и максимумы'!I$2)/('минимумы и максимумы'!I$4-'минимумы и максимумы'!I$2)*100) -> 3.5714286 | ... U6: =IF('исходные данные'!U6>'минимумы и максимумы'!S$4,100,('исходные данные'!U6-'минимумы и максимумы'!S$2)/('минимумы и максимумы'!S$4-'минимумы и максимумы'!S$2)*100) -> 100
